Workbook

Sheet SV Extract_OP Revenue wo Equip
C1: 44957 | F1: 44985 | I1: 45016 | L1: 45046
A2: Freedom_GL | B2: Description | C2: SV | D2: GL | E2: Variance | F2: SV | G2: GL | H2: Variance | I2: SV | J2: GL | K2: Variance | L2: SV | M2: GL | N2: Variance | O2: Comment
A3: 400200 | B3: Connection Fees | C3: 410207.5 | D3: =VLOOKUP($A3,'Gross Margin Details'!$A:$F,3,FALSE) -> 563525.02 | E3: =D3-C3 -> 153317.52 | F3: 374382.5 | G3: =VLOOKUP($A3,'Gross Margin Details'!$A:$F,4,FALSE) -> 549904.93 | H3: =G3-F3 -> 175522.43 | I3: 319992.5 | J3: =VLOOKUP($A3,'Gross Margin Details'!$A:$F,5,FALSE) -> 514040 | K3: =J3-I3 -> 194047.5 | L3: 216425 | M3: =VLOOKUP($A3,'Gross Margin Details'!$A:$F,6,FALSE) -> 517207.74 | N3: =M3-L3 -> 300782.74 | O3: company 197 continuity
A4: 400300 | B4: Monthly Fees | C4: 8205720.5 | D4: =VLOOKUP($A4,'Gross Margin Details'!$A:$F,3,FALSE) -> 8162712.6 | E4: =D4-C4 -> -43007.9 | F4: 8346479.7 | G4: =VLOOKUP($A4,'Gross Margin Details'!$A:$F,4,FALSE) -> 7953849.1 | H4: =G4-F4 -> -392630.64 | I4: 8416769 | J4: =VLOOKUP($A4,'Gross Margin Details'!$A:$F,5,FALSE) -> 8928200.8 | K4: =J4-I4 -> 511431.86 | L4: 8392945.1 | M4: =VLOOKUP($A4,'Gross Margin Details'!$A:$F,6,FALSE) -> 8286992.6 | N4: =M4-L4 -> -105952.54 | O4: deferred revenue
A5: 400303 | B5: Phone Protection Revenue | D5: =VLOOKUP($A5,'Gross Margin Details'!$A:$F,3,FALSE) -> 90799.19 | E5: =D5-C5 -> 90799.19 | G5: =VLOOKUP($A5,'Gross Margin Details'!$A:$F,4,FALSE) -> 83034.68 | H5: =G5-F5 -> 83034.68 | J5: =VLOOKUP($A5,'Gross Margin Details'!$A:$F,5,FALSE) -> 102395.22 | K5: =J5-I5 -> 102395.22 | M5: =VLOOKUP($A5,'Gross Margin Details'!$A:$F,6,FALSE) -> 89667.28 | N5: =M5-L5 -> 89667.28 | O5: Manual JE
A6: 400308 | B6: Above MRC Discounts | C6: -19.96 | D6: =VLOOKUP($A6,'Gross Margin Details'!$A:$F,3,FALSE) -> -19.96 | E6: =D6-C6 -> 0 | G6: =VLOOKUP($A6,'Gross Margin Details'!$A:$F,4,FALSE) -> -2.25 | H6: =G6-F6 -> -2.25 | J6: =VLOOKUP($A6,'Gross Margin Details'!$A:$F,5,FALSE) -> 0 | K6: =J6-I6 -> 0 | M6: =VLOOKUP($A6,'Gross Margin Details'!$A:$F,6,FALSE) -> 0 | N6: =M6-L6 -> 0
A7: 400309 | B7: Credit Monthly Fees | C7: -231679.12 | D7: =VLOOKUP($A7,'Gross Margin Details'!$A:$F,3,FALSE) -> -289795.36 | E7: =D7-C7 -> -58116.24 | F7: -221869.53 | G7: =VLOOKUP($A7,'Gross Margin Details'!$A:$F,4,FALSE) -> -265553.36 | H7: =G7-F7 -> -43683.83 | I7: -178453.4 | J7: =VLOOKUP($A7,'Gross Margin Details'!$A:$F,5,FALSE) -> -216702.86 | K7: =J7-I7 -> -38249.46 | L7: -117316.04 | M7: =VLOOKUP($A7,'Gross Margin Details'!$A:$F,6,FALSE) -> -131889.81 | N7: =M7-L7 -> -14573.77 | O7: deferred revenue
A8: 400399 | B8: Monthly Discount Fees | C8: -124912.62 | D8: =VLOOKUP($A8,'Gross Margin Details'!$A:$F,3,FALSE) -> -120333.21 | E8: =D8-C8 -> 4579.41 | F8: -130823.28 | G8: =VLOOKUP($A8,'Gross Margin Details'!$A:$F,4,FALSE) -> -130259.44 | H8: =G8-F8 -> 563.84 | I8: -119540.49 | J8: =VLOOKUP($A8,'Gross Margin Details'!$A:$F,5,FALSE) -> -118908.75 | K8: =J8-I8 -> 631.74 | L8: -127589.56 | M8: =VLOOKUP($A8,'Gross Margin Details'!$A:$F,6,FALSE) -> -126822.32 | N8: =M8-L8 -> 767.24 | O8: deferred revenue
A9: 401121 | B9: International | C9: 136859.62 | D9: =VLOOKUP($A9,'Gross Margin Details'!$A:$F,3,FALSE) -> 136859.62 | E9: =D9-C9 -> 1.7986167e-08 | F9: 128170.39 | G9: =VLOOKUP($A9,'Gross Margin Details'!$A:$F,4,FALSE) -> 128170.39 | H9: =G9-F9 -> 1.3998942e-08 | I9: 115984.88 | J9: =VLOOKUP($A9,'Gross Margin Details'!$A:$F,5,FALSE) -> 115984.88 | K9: =J9-I9 -> 1.3009412e-08 | L9: 127048.34 | M9: =VLOOKUP($A9,'Gross Margin Details'!$A:$F,6,FALSE) -> 127048.34 | N9: =M9-L9 -> 1.3998942e-08 | O9: deferred revenue
A10: 401171 | B10: National Long Distance | C10: 44194.87 | D10: =VLOOKUP($A10,'Gross Margin Details'!$A:$F,3,FALSE) -> 44171.2 | E10: =D10-C10 -> -23.67 | F10: 44811.06 | G10: =VLOOKUP($A10,'Gross Margin Details'!$A:$F,4,FALSE) -> 42611 | H10: =G10-F10 -> -2200.06 | I10: 45512.29 | J10: =VLOOKUP($A10,'Gross Margin Details'!$A:$F,5,FALSE) -> 47217.93 | K10: =J10-I10 -> 1705.64 | L10: 45719.93 | M10: =VLOOKUP($A10,'Gross Margin Details'!$A:$F,6,FALSE) -> 45043.62 | N10: =M10-L10 -> -676.31 | O10: deferred revenue
A11: 401200 | B11: Mobile Internet | C11: 194215.09 | D11: =VLOOKUP($A11,'Gross Margin Details'!$A:$F,3,FALSE) -> 194076.97 | E11: =D11-C11 -> -138.12 | F11: 196381.35 | G11: =VLOOKUP($A11,'Gross Margin Details'!$A:$F,4,FALSE) -> 186723.74 | H11: =G11-F11 -> -9657.61 | I11: 197724.76 | J11: =VLOOKUP($A11,'Gross Margin Details'!$A:$F,5,FALSE) -> 205886 | K11: =J11-I11 -> 8161.24 | L11: 199786.02 | M11: =VLOOKUP($A11,'Gross Margin Details'!$A:$F,6,FALSE) -> 195941.13 | N11: =M11-L11 -> -3844.89 | O11: deferred revenue
A12: 401400 | B12: VAS | C12: 23676.5 | D12: =VLOOKUP($A12,'Gross Margin Details'!$A:$F,3,FALSE) -> 23671.42 | E12: =D12-C12 -> -5.08 | F12: 24012.7 | G12: =VLOOKUP($A12,'Gross Margin Details'!$A:$F,4,FALSE) -> 22795.42 | H12: =G12-F12 -> -1217.28 | I12: 23814.54 | J12: =VLOOKUP($A12,'Gross Margin Details'!$A:$F,5,FALSE) -> 24982.83 | K12: =J12-I12 -> 1168.29 | L12: 23861.29 | M12: =VLOOKUP($A12,'Gross Margin Details'!$A:$F,6,FALSE) -> 23509.47 | N12: =M12-L12 -> -351.82 | O12: deferred revenue
A13: 401411 | B13: VAS Usage | C13: 12151.11 | D13: =VLOOKUP($A13,'Gross Margin Details'!$A:$F,3,FALSE) -> 12151.11 | E13: =D13-C13 -> -3.0013325e-10 | F13: 12017.08 | G13: =VLOOKUP($A13,'Gross Margin Details'!$A:$F,4,FALSE) -> 12017.08 | H13: =G13-F13 -> -3.0013325e-10 | I13: 11652.78 | J13: =VLOOKUP($A13,'Gross Margin Details'!$A:$F,5,FALSE) -> 11652.78 | K13: =J13-I13 -> -3.0013325e-10 | L13: 11163.06 | M13: =VLOOKUP($A13,'Gross Margin Details'!$A:$F,6,FALSE) -> 11163.06 | N13: =M13-L13 -> 0 | O13: deferred revenue
A14: 404000 | B14: International Roaming | C14: 92456.5 | D14: =VLOOKUP($A14,'Gross Margin Details'!$A:$F,3,FALSE) -> 92456.5 | E14: =D14-C14 -> 0 | F14: 80962.5 | G14: =VLOOKUP($A14,'Gross Margin Details'!$A:$F,4,FALSE) -> 80962.5 | H14: =G14-F14 -> 0 | I14: 74776.5 | J14: =VLOOKUP($A14,'Gross Margin Details'!$A:$F,5,FALSE) -> 74776.5 | K14: =J14-I14 -> 0 | L14: 83696.5 | M14: =VLOOKUP($A14,'Gross Margin Details'!$A:$F,6,FALSE) -> 83696.5 | N14: =M14-L14 -> 0 | O14: deferred revenue
A15: 404200 | B15: Mobile Internet Intl Roaming | C15: 563102.97 | D15: =VLOOKUP($A15,'Gross Margin Details'!$A:$F,3,FALSE) -> 553203.91 | E15: =D15-C15 -> -9899.06 | F15: 535153.06 | G15: =VLOOKUP($A15,'Gross Margin Details'!$A:$F,4,FALSE) -> 504865.15 | H15: =G15-F15 -> -30287.91 | I15: 553322.49 | J15: =VLOOKUP($A15,'Gross Margin Details'!$A:$F,5,FALSE) -> 557860.79 | K15: =J15-I15 -> 4538.3 | L15: 658601.23 | M15: =VLOOKUP($A15,'Gross Margin Details'!$A:$F,6,FALSE) -> 653211.2 | N15: =M15-L15 -> -5390.03 | O15: deferred revenue
A16: 404500 | B16: Domestic Roaming | C16: 5718.77 | D16: =VLOOKUP($A16,'Gross Margin Details'!$A:$F,3,FALSE) -> 5718.77 | E16: =D16-C16 -> 5.0022209e-11 | F16: 4798.74 | G16: =VLOOKUP($A16,'Gross Margin Details'!$A:$F,4,FALSE) -> 4798.74 | H16: =G16-F16 -> -1.0004442e-11 | I16: 3814.52 | J16: =VLOOKUP($A16,'Gross Margin Details'!$A:$F,5,FALSE) -> 3814.52 | K16: =J16-I16 -> -3.0013325e-11 | L16: 4321.03 | M16: =VLOOKUP($A16,'Gross Margin Details'!$A:$F,6,FALSE) -> 4321.03 | N16: =M16-L16 -> -3.0013325e-11 | O16: deferred revenue
A17: 404510 | B17: SMS International Roaming | C17: 28566 | D17: =VLOOKUP($A17,'Gross Margin Details'!$A:$F,3,FALSE) -> 28566 | E17: =D17-C17 -> 0 | F17: 20806.5 | G17: =VLOOKUP($A17,'Gross Margin Details'!$A:$F,4,FALSE) -> 20806.5 | H17: =G17-F17 -> 0 | I17: 22468.5 | J17: =VLOOKUP($A17,'Gross Margin Details'!$A:$F,5,FALSE) -> 22468.5 | K17: =J17-I17 -> 0 | L17: 29712.5 | M17: =VLOOKUP($A17,'Gross Margin Details'!$A:$F,6,FALSE) -> 29712.5 | N17: =M17-L17 -> 0 | O17: deferred revenue
A18: 405210 | B18: Mobile Internet Domestic Roaming | C18: 320817.29 | D18: =VLOOKUP($A18,'Gross Margin Details'!$A:$F,3,FALSE) -> 320164.72 | E18: =D18-C18 -> -652.57 | F18: 343575.82 | G18: =VLOOKUP($A18,'Gross Margin Details'!$A:$F,4,FALSE) -> 316483.13 | H18: =G18-F18 -> -27092.69 | I18: 313131.7 | J18: =VLOOKUP($A18,'Gross Margin Details'!$A:$F,5,FALSE) -> 343114.58 | K18: =J18-I18 -> 29982.88 | L18: 362748.56 | M18: =VLOOKUP($A18,'Gross Margin Details'!$A:$F,6,FALSE) -> 335574.21 | N18: =M18-L18 -> -27174.35 | O18: deferred revenue
... A21: 406001 | B21: Extended Warranty Commissions Revenue | C21: 166188.78 | D21: =VLOOKUP($A21,'Gross Margin Details'!$A:$F,3,FALSE) -> 0 | E21: =D21-C21 -> -166188.78 | F21: 166033.34 | G21: =VLOOKUP($A21,'Gross Margin Details'!$A:$F,4,FALSE) -> 0 | H21: =G21-F21 -> -166033.34 | I21: 167528.47 | J21: =VLOOKUP($A21,'Gross Margin Details'!$A:$F,5,FALSE) -> 0 | K21: =J21-I21 -> -167528.47 | L21: 165537.1 | M21: =VLOOKUP($A21,'Gross Margin Details'!$A:$F,6,FALSE) -> 0 | N21: =M21-L21 -> -165537.1 | O21: Manual JE
A22: 406003 | B22: Apple Care | D22: =VLOOKUP($A22,'Gross Margin Details'!$A:$F,3,FALSE) -> 122 | E22: =D22-C22 -> 122 | G22: =VLOOKUP($A22,'Gross Margin Details'!$A:$F,4,FALSE) -> 2566 | H22: =G22-F22 -> 2566 | J22: =VLOOKUP($A22,'Gross Margin Details'!$A:$F,5,FALSE) -> 4042 | K22: =J22-I22 -> 4042 | M22: =VLOOKUP($A22,'Gross Margin Details'!$A:$F,6,FALSE) -> -479 | N22: =M22-L22 -> -479 | O22: Manual JE
A23: 406010 | B23: 911 Levy Revenue | C23: -84173.8 | D23: =VLOOKUP($A23,'Gross Margin Details'!$A:$F,3,FALSE) -> -67664.37 | E23: =D23-C23 -> 16509.43 | F23: -83613.3 | G23: =VLOOKUP($A23,'Gross Margin Details'!$A:$F,4,FALSE) -> -67038.21 | H23: =G23-F23 -> 16575.09 | I23: -83211.45 | J23: =VLOOKUP($A23,'Gross Margin Details'!$A:$F,5,FALSE) -> -66509.45 | K23: =J23-I23 -> 16702 | L23: -82547.4 | M23: =VLOOKUP($A23,'Gross Margin Details'!$A:$F,6,FALSE) -> -65733.96 | N23: =M23-L23 -> 16813.44 | O23: Manual JE
A24: Subtotal | C24: =SUM(C3:C23) -> 9777244.7 | D24: =SUM(D3:D23) -> 9744350.2 | E24: =SUM(E3:E23) -> -32894.55 | F24: =SUM(F3:F23) -> 9854851.2 | G24: =SUM(G3:G23) -> 9458540.2 | H24: =SUM(H3:H23) -> -396310.99 | I24: =SUM(I3:I23) -> 9899354.3 | J24: =SUM(J3:J23) -> 10566584 | ... N24: =SUM(N3:N23) -> 83646.63
C25: =C24-[1]Summary!$AK$54 -> 0 | D25: =D24-'Gross Margin Details'!C127 -> 0 | F25: =F24-[1]Summary!$Y$54 -> 0 | G25: =G24-'Gross Margin Details'!D127 -> 0 | I25: =I24-[1]Summary!$N$54 -> 0 | J25: =J24-'Gross Margin Details'!E127 -> 0 | L25: =L24-[1]Summary!$C$54 -> 0 | M25: =M24-'Gross Margin Details'!F127 -> 0

Sheet Gross Margin Details
B1: Last Refresh: 5/5/2023 9:44:15 AM
B2: Shaw Finance
B3: WLS01 Financials
B4: W1 Wireless Brand - Shaw Mobile
B5: #Versions: Reporting - Current Forecast
A6: Freedom_GL | C6: =CHOOSE(2, "5449260031", "Jan 23") -> Jan 23 | D6: =CHOOSE(2, "5449570028", "Feb 23") -> Feb 23 | E6: =CHOOSE(2, "5449850031", "Mar 23") -> Mar 23 | F6: =CHOOSE(2, "5450160030", "Apr 23") -> Apr 23
B7: =CHOOSE(2, "415000000058", "Wireless Revenue & Variable Cost Details") -> Wireless Revenue & Variable Cost Details
B8: =CHOOSE(2, "415000000147", "Service Revenue Details") -> Service Revenue Details
A9: 400300 | B9: =CHOOSE(2, "415000000060", "Postpaid - Base Plan MRC - Phone") -> Postpaid - Base Plan MRC - Phone | C9: 8162712.6 | D9: 7953849.1 | E9: 8928200.8 | F9: 8286992.6
B10: =CHOOSE(2, "415000000061", "Postpaid - Base Plan MRC - Tablets") -> Postpaid - Base Plan MRC - Tablets | C10: 0 | D10: 0 | E10: 0 | F10: 0
A11: 400309 | B11: =CHOOSE(2, "415000000062", "Postpaid - MRC Discounts") -> Postpaid - MRC Discounts | C11: -289795.36 | D11: -265553.36 | E11: -216702.86 | F11: -131889.81
A12: 401171 | B12: =CHOOSE(2, "415000000063", "Postpaid - Add on - LD - Domestic - Voice") -> Postpaid - Add on - LD - Domestic - Voice | C12: 44171.2 | D12: 42611 | E12: 47217.93 | F12: 45043.62
B13: =CHOOSE(2, "415000000064", "Postpaid - Add on - LD - International - Voice") -> Postpaid - Add on - LD - International - Voice | C13: 0 | D13: 0 | E13: 0 | F13: 0
A14: 401200 | B14: =CHOOSE(2, "415000000065", "Postpaid - Add on - Data - Domestic - MB") -> Postpaid - Add on - Data - Domestic - MB | C14: 194076.97 | D14: 186723.74 | E14: 205886 | F14: 195941.13
A15: 401400 | B15: =CHOOSE(2, "415000000066", "Postpaid - Add on - VAS - Domestic - VAS") -> Postpaid - Add on - VAS - Domestic - VAS | C15: 23671.42 | D15: 22795.42 | E15: 24982.83 | F15: 23509.47
B16: =CHOOSE(2, "415000000067", "Postpaid - Add on - VAS - Domestic - SMS") -> Postpaid - Add on - VAS - Domestic - SMS | C16: 0 | D16: 0 | E16: 0 | F16: 0
B17: =CHOOSE(2, "415000000068", "Postpaid - Overage - LD - Domestic - Voice - Local") -> Postpaid - Overage - LD - Domestic - Voice - Local | C17: 0 | D17: 0 | E17: 0 | F17: 0
B18: =CHOOSE(2, "415000000069", "Postpaid - Overage - LD - Domestic - Voice - National LD") -> Postpaid - Overage - LD - Domestic - Voice - National LD | C18: 0 | D18: 0 | E18: 0 | F18: 0
A19: 401121 | B19: =CHOOSE(2, "415000000070", "Postpaid - Overage - LD - International - Voice - Intl.") -> Postpaid - Overage - LD - International - Voice - Intl. | C19: 136859.62 | D19: 128170.39 | E19: 115984.88 | F19: 127048.34
B20: =CHOOSE(2, "415000000071", "Postpaid - Overage - Data - Domestic - MB") -> Postpaid - Overage - Data - Domestic - MB | C20: 0 | D20: 0 | E20: 0 | F20: 0
A21: 401411 | B21: =CHOOSE(2, "415000000072", "Postpaid - Overage - VAS - Domestic - VAS") -> Postpaid - Overage - VAS - Domestic - VAS | C21: 12151.11 | D21: 12017.08 | E21: 11652.78 | F21: 11163.06
B22: =CHOOSE(2, "415000000073", "Postpaid - Overage - VAS - Domestic - SMS") -> Postpaid - Overage - VAS - Domestic - SMS | C22: 0 | D22: 0 | E22: 0 | F22: 0
B23: =CHOOSE(2, "415000000074", "Postpaid - Overage - VAS - International - SMS") -> Postpaid - Overage - VAS - International - SMS | C23: 0 | D23: 0 | E23: 0 | F23: 0
A24: 404000 | B24: =CHOOSE(2, "415000000075", "Postpaid - Overage - Roaming - International Roaming - Voice") -> Postpaid - Overage - Roaming - International Roaming - Voice | C24: 92456.5 | D24: 80962.5 | E24: 74776.5 | F24: 83696.5
A25: 404200 | B25: =CHOOSE(2, "415000000076", "Postpaid - Overage - Roaming - International Roaming - MB") -> Postpaid - Overage - Roaming - International Roaming - MB | C25: 553203.91 | D25: 504865.15 | E25: 557860.79 | F25: 653211.2
A26: 404510 | B26: =CHOOSE(2, "415000000077", "Postpaid - Overage - Roaming - International Roaming - SMS") -> Postpaid - Overage - Roaming - International Roaming - SMS | C26: 28566 | D26: 20806.5 | E26: 22468.5 | F26: 29712.5
A27: 404500 | B27: =CHOOSE(2, "415000000078", "Postpaid - Overage - Roaming - Domestic Roaming - Voice") -> Postpaid - Overage - Roaming - Domestic Roaming - Voice | C27: 5718.77 | D27: 4798.74 | E27: 3814.52 | F27: 4321.03
A28: 405210 | B28: =CHOOSE(2, "415000000079", "Postpaid - Overage - Roaming - Domestic Roaming - MB") -> Postpaid - Overage - Roaming - Domestic Roaming - MB | C28: 320164.72 | D28: 316483.13 | E28: 343114.58 | F28: 335574.21
A29: 405500 | B29: =CHOOSE(2, "415000000080", "Postpaid - Overage - Roaming - Domestic Roaming - SMS") -> Postpaid - Overage - Roaming - Domestic Roaming - SMS | C29: 223.25 | D29: 223.5 | E29: 154.75 | F29: 162.2
B30: =CHOOSE(2, "415000000081", "Postpaid - Overage - Tablets - Data - Domestic - MB") -> Postpaid - Overage - Tablets - Data - Domestic - MB | C30: 0 | D30: 0 | E30: 0 | F30: 0
A31: 400200 | B31: =CHOOSE(2, "415000000082", "Postpaid - Other - Connection Fees") -> Postpaid - Other - Connection Fees | C31: 563525.02 | D31: 549904.93 | E31: 514040 | F31: 517207.74
A32: 400303 | B32: =CHOOSE(2, "415000000083", "Postpaid - Other - Phone Protection") -> Postpaid - Other - Phone Protection | C32: 90799.19 | D32: 83034.68 | E32: 102395.22 | F32: 89667.28
A33: 400308 | B33: =CHOOSE(2, "415000000084", "Postpaid - Credit & Adjustment - Above MRC Disc.") -> Postpaid - Credit & Adjustment - Above MRC Disc. | C33: -19.96 | D33: -2.25 | E33: 0 | F33: 0
A34: 400399 | B34: =CHOOSE(2, "415000000085", "Postpaid - Credit & Adjustment - Cust. Service Adj.") -> Postpaid - Credit & Adjustment - Cust. Service Adj. | C34: -120333.21 | D34: -130259.44 | E34: -118908.75 | F34: -126822.32
B35: =CHOOSE(2, "415000000086", "Postpaid - Disc. Amort. Allocated to/from Wireline") -> Postpaid - Disc. Amort. Allocated to/from Wireline | C35: 5065778.4 | D35: 5062325.4 | E35: 5059109.8 | F35: 5046943.8
B36: =CHOOSE(2, "415000000087", "Postpaid - Disc. Amort. Allocated to/from HS") -> Postpaid - Disc. Amort. Allocated to/from HS | C36: 221207.7 | D36: 216357.84 | E36: 219428.06 | F36: 222446.49
B37: =CHOOSE(2, "415000000059", "Service Revenue - Postpaid") -> Service Revenue - Postpaid | C37: 15105138 | D37: 14790114 | E37: 15895476 | F37: 15413929
B38: =CHOOSE(2, "415000000115", "Visitor Roaming") -> Visitor Roaming | C38: 0 | D38: 0 | E38: 0 | F38: 0
B39: =CHOOSE(2, "415000000116", "Service Revenue - Total") -> Service Revenue - Total | C39: 15105138 | D39: 14790114 | E39: 15895476 | F39: 15413929
B40: =CHOOSE(2, "415000000148", "Equipment Revenue Details") -> Equipment Revenue Details
...
